[2019-11-26 17:24:51 +0000] [18979] [DEBUG] Current configuration:
  config: None
  bind: ['localhost:5000']
  backlog: 2048
  workers: 2
  worker_class: sync
  threads: 2
  worker_connections: 1000
  max_requests: 0
  max_requests_jitter: 0
  timeout: 30
  graceful_timeout: 30
  keepalive: 2
  limit_request_line: 4094
  limit_request_fields: 100
  limit_request_field_size: 8190
  reload: False
  reload_engine: auto
  reload_extra_files: []
  spew: False
  check_config: False
  preload_app: False
  sendfile: None
  reuse_port: False
  chdir: /home/ubuntu/FAQExtractor
  daemon: False
  raw_env: []
  pidfile: None
  worker_tmp_dir: None
  user: 1000
  group: 1000
  umask: 0
  initgroups: False
  tmp_upload_dir: None
  secure_scheme_headers: {'X-FORWARDED-PROTOCOL': 'ssl', 'X-FORWARDED-PROTO': 'https', 'X-FORWARDED-SSL': 'on'}
  forwarded_allow_ips: ['127.0.0.1']
  accesslog: out.log
  disable_redirect_access_to_syslog: False
  access_log_format: %(h)s %(l)s %(u)s %(t)s "%(r)s" %(s)s %(b)s "%(f)s" "%(a)s"
  errorlog: err.log
  loglevel: debug
  capture_output: True
  logger_class: gunicorn.glogging.Logger
  logconfig: None
  logconfig_dict: {}
  syslog_addr: udp://localhost:514
  syslog: False
  syslog_prefix: None
  syslog_facility: user
  enable_stdio_inheritance: False
  statsd_host: None
  dogstatsd_tags: 
  statsd_prefix: 
  proc_name: None
  default_proc_name: QnAApi:app
  pythonpath: None
  paste: None
  on_starting: <function OnStarting.on_starting at 0x7f98d360a510>
  on_reload: <function OnReload.on_reload at 0x7f98d360a620>
  when_ready: <function WhenReady.when_ready at 0x7f98d360a730>
  pre_fork: <function Prefork.pre_fork at 0x7f98d360a840>
  post_fork: <function Postfork.post_fork at 0x7f98d360a950>
  post_worker_init: <function PostWorkerInit.post_worker_init at 0x7f98d360aa60>
  worker_int: <function WorkerInt.worker_int at 0x7f98d360ab70>
  worker_abort: <function WorkerAbort.worker_abort at 0x7f98d360ac80>
  pre_exec: <function PreExec.pre_exec at 0x7f98d360ad90>
  pre_request: <function PreRequest.pre_request at 0x7f98d360aea0>
  post_request: <function PostRequest.post_request at 0x7f98d360af28>
  child_exit: <function ChildExit.child_exit at 0x7f98d36270d0>
  worker_exit: <function WorkerExit.worker_exit at 0x7f98d36271e0>
  nworkers_changed: <function NumWorkersChanged.nworkers_changed at 0x7f98d36272f0>
  on_exit: <function OnExit.on_exit at 0x7f98d3627400>
  proxy_protocol: False
  proxy_allow_ips: ['127.0.0.1']
  keyfile: None
  certfile: None
  ssl_version: 2
  cert_reqs: 0
  ca_certs: None
  suppress_ragged_eofs: True
  do_handshake_on_connect: False
  ciphers: None
  raw_paste_global_conf: []
[2019-11-26 17:24:51 +0000] [18979] [INFO] Starting gunicorn 20.0.0
[2019-11-26 17:24:51 +0000] [18979] [ERROR] Connection in use: ('localhost', 5000)
[2019-11-26 17:24:51 +0000] [18979] [DEBUG] connection to ('localhost', 5000) failed: [Errno 98] Address already in use
[2019-11-26 17:24:51 +0000] [18979] [ERROR] Retrying in 1 second.
[2019-11-26 17:24:52 +0000] [18979] [ERROR] Connection in use: ('localhost', 5000)
[2019-11-26 17:24:52 +0000] [18979] [DEBUG] connection to ('localhost', 5000) failed: [Errno 98] Address already in use
[2019-11-26 17:24:52 +0000] [18979] [ERROR] Retrying in 1 second.
[2019-11-26 17:24:53 +0000] [18979] [ERROR] Connection in use: ('localhost', 5000)
[2019-11-26 17:24:53 +0000] [18979] [DEBUG] connection to ('localhost', 5000) failed: [Errno 98] Address already in use
[2019-11-26 17:24:53 +0000] [18979] [ERROR] Retrying in 1 second.
[2019-11-26 17:24:54 +0000] [18979] [ERROR] Connection in use: ('localhost', 5000)
[2019-11-26 17:24:54 +0000] [18979] [DEBUG] connection to ('localhost', 5000) failed: [Errno 98] Address already in use
[2019-11-26 17:24:54 +0000] [18979] [ERROR] Retrying in 1 second.
[2019-11-26 17:24:55 +0000] [18979] [ERROR] Connection in use: ('localhost', 5000)
[2019-11-26 17:24:55 +0000] [18979] [DEBUG] connection to ('localhost', 5000) failed: [Errno 98] Address already in use
[2019-11-26 17:24:55 +0000] [18979] [ERROR] Retrying in 1 second.
[2019-11-26 17:24:56 +0000] [18979] [ERROR] Can't connect to ('localhost', 5000)
[2019-11-28 10:41:08 +0000] [23659] [DEBUG] Current configuration:
  config: None
  bind: ['localhost:5000']
  backlog: 2048
  workers: 2
  worker_class: sync
  threads: 2
  worker_connections: 1000
  max_requests: 0
  max_requests_jitter: 0
  timeout: 30
  graceful_timeout: 30
  keepalive: 2
  limit_request_line: 4094
  limit_request_fields: 100
  limit_request_field_size: 8190
  reload: False
  reload_engine: auto
  reload_extra_files: []
  spew: False
  check_config: False
  preload_app: False
  sendfile: None
  reuse_port: False
  chdir: /home/ubuntu/FAQExtractor
  daemon: False
  raw_env: []
  pidfile: None
  worker_tmp_dir: None
  user: 1000
  group: 1000
  umask: 0
  initgroups: False
  tmp_upload_dir: None
  secure_scheme_headers: {'X-FORWARDED-PROTOCOL': 'ssl', 'X-FORWARDED-PROTO': 'https', 'X-FORWARDED-SSL': 'on'}
  forwarded_allow_ips: ['127.0.0.1']
  accesslog: out.log
  disable_redirect_access_to_syslog: False
  access_log_format: %(h)s %(l)s %(u)s %(t)s "%(r)s" %(s)s %(b)s "%(f)s" "%(a)s"
  errorlog: err.log
  loglevel: debug
  capture_output: True
  logger_class: gunicorn.glogging.Logger
  logconfig: None
  logconfig_dict: {}
  syslog_addr: udp://localhost:514
  syslog: False
  syslog_prefix: None
  syslog_facility: user
  enable_stdio_inheritance: False
  statsd_host: None
  dogstatsd_tags: 
  statsd_prefix: 
  proc_name: None
  default_proc_name: QnAApi:app
  pythonpath: None
  paste: None
  on_starting: <function OnStarting.on_starting at 0x7fcb9c964510>
  on_reload: <function OnReload.on_reload at 0x7fcb9c964620>
  when_ready: <function WhenReady.when_ready at 0x7fcb9c964730>
  pre_fork: <function Prefork.pre_fork at 0x7fcb9c964840>
  post_fork: <function Postfork.post_fork at 0x7fcb9c964950>
  post_worker_init: <function PostWorkerInit.post_worker_init at 0x7fcb9c964a60>
  worker_int: <function WorkerInt.worker_int at 0x7fcb9c964b70>
  worker_abort: <function WorkerAbort.worker_abort at 0x7fcb9c964c80>
  pre_exec: <function PreExec.pre_exec at 0x7fcb9c964d90>
  pre_request: <function PreRequest.pre_request at 0x7fcb9c964ea0>
  post_request: <function PostRequest.post_request at 0x7fcb9c964f28>
  child_exit: <function ChildExit.child_exit at 0x7fcb9c9820d0>
  worker_exit: <function WorkerExit.worker_exit at 0x7fcb9c9821e0>
  nworkers_changed: <function NumWorkersChanged.nworkers_changed at 0x7fcb9c9822f0>
  on_exit: <function OnExit.on_exit at 0x7fcb9c982400>
  proxy_protocol: False
  proxy_allow_ips: ['127.0.0.1']
  keyfile: None
  certfile: None
  ssl_version: 2
  cert_reqs: 0
  ca_certs: None
  suppress_ragged_eofs: True
  do_handshake_on_connect: False
  ciphers: None
  raw_paste_global_conf: []
[2019-11-28 10:41:08 +0000] [23659] [INFO] Starting gunicorn 20.0.0
[2019-11-28 10:41:08 +0000] [23659] [DEBUG] Arbiter booted
[2019-11-28 10:41:08 +0000] [23659] [INFO] Listening at: http://127.0.0.1:5000 (23659)
[2019-11-28 10:41:08 +0000] [23659] [INFO] Using worker: threads
[2019-11-28 10:41:08 +0000] [23663] [INFO] Booting worker with pid: 23663
[2019-11-28 10:41:08 +0000] [23663] [ERROR] Exception in worker process
Traceback (most recent call last):
  File "/home/ubuntu/.local/lib/python3.6/site-packages/gunicorn/arbiter.py", line 583, in spawn_worker
    worker.init_process()
  File "/home/ubuntu/.local/lib/python3.6/site-packages/gunicorn/workers/gthread.py", line 92, in init_process
    super().init_process()
  File "/home/ubuntu/.local/lib/python3.6/site-packages/gunicorn/workers/base.py", line 133, in init_process
    self.load_wsgi()
  File "/home/ubuntu/.local/lib/python3.6/site-packages/gunicorn/workers/base.py", line 142, in load_wsgi
    self.wsgi = self.app.wsgi()
  File "/home/ubuntu/.local/lib/python3.6/site-packages/gunicorn/app/base.py", line 67, in wsgi
    self.callable = self.load()
  File "/home/ubuntu/.local/lib/python3.6/site-packages/gunicorn/app/wsgiapp.py", line 49, in load
    return self.load_wsgiapp()
  File "/home/ubuntu/.local/lib/python3.6/site-packages/gunicorn/app/wsgiapp.py", line 39, in load_wsgiapp
    return util.import_app(self.app_uri)
  File "/home/ubuntu/.local/lib/python3.6/site-packages/gunicorn/util.py", line 331, in import_app
    mod = importlib.import_module(module)
  File "/usr/lib/python3.6/importlib/__init__.py", line 126, in import_module
    return _bootstrap._gcd_import(name[level:], package, level)
  File "<frozen importlib._bootstrap>", line 994, in _gcd_import
  File "<frozen importlib._bootstrap>", line 971, in _find_and_load
  File "<frozen importlib._bootstrap>", line 953, in _find_and_load_unlocked
ModuleNotFoundError: No module named 'QnAApi'
[2019-11-28 10:41:08 +0000] [23663] [INFO] Worker exiting (pid: 23663)
[2019-11-28 10:41:08 +0000] [23659] [INFO] Shutting down: Master
[2019-11-28 10:41:08 +0000] [23659] [INFO] Reason: Worker failed to boot.
[2019-11-28 10:41:59 +0000] [23666] [DEBUG] Current configuration:
  config: None
  bind: ['localhost:5000']
  backlog: 2048
  workers: 2
  worker_class: sync
  threads: 2
  worker_connections: 1000
  max_requests: 0
  max_requests_jitter: 0
  timeout: 30
  graceful_timeout: 30
  keepalive: 2
  limit_request_line: 4094
  limit_request_fields: 100
  limit_request_field_size: 8190
  reload: False
  reload_engine: auto
  reload_extra_files: []
  spew: False
  check_config: False
  preload_app: False
  sendfile: None
  reuse_port: False
  chdir: /home/ubuntu/FAQExtractor
  daemon: False
  raw_env: []
  pidfile: None
  worker_tmp_dir: None
  user: 1000
  group: 1000
  umask: 0
  initgroups: False
  tmp_upload_dir: None
  secure_scheme_headers: {'X-FORWARDED-PROTOCOL': 'ssl', 'X-FORWARDED-PROTO': 'https', 'X-FORWARDED-SSL': 'on'}
  forwarded_allow_ips: ['127.0.0.1']
  accesslog: out.log
  disable_redirect_access_to_syslog: False
  access_log_format: %(h)s %(l)s %(u)s %(t)s "%(r)s" %(s)s %(b)s "%(f)s" "%(a)s"
  errorlog: err.log
  loglevel: debug
  capture_output: True
  logger_class: gunicorn.glogging.Logger
  logconfig: None
  logconfig_dict: {}
  syslog_addr: udp://localhost:514
  syslog: False
  syslog_prefix: None
  syslog_facility: user
  enable_stdio_inheritance: False
  statsd_host: None
  dogstatsd_tags: 
  statsd_prefix: 
  proc_name: None
  default_proc_name: QnAApi:app
  pythonpath: None
  paste: None
  on_starting: <function OnStarting.on_starting at 0x7f56533fc510>
  on_reload: <function OnReload.on_reload at 0x7f56533fc620>
  when_ready: <function WhenReady.when_ready at 0x7f56533fc730>
  pre_fork: <function Prefork.pre_fork at 0x7f56533fc840>
  post_fork: <function Postfork.post_fork at 0x7f56533fc950>
  post_worker_init: <function PostWorkerInit.post_worker_init at 0x7f56533fca60>
  worker_int: <function WorkerInt.worker_int at 0x7f56533fcb70>
  worker_abort: <function WorkerAbort.worker_abort at 0x7f56533fcc80>
  pre_exec: <function PreExec.pre_exec at 0x7f56533fcd90>
  pre_request: <function PreRequest.pre_request at 0x7f56533fcea0>
  post_request: <function PostRequest.post_request at 0x7f56533fcf28>
  child_exit: <function ChildExit.child_exit at 0x7f56534190d0>
  worker_exit: <function WorkerExit.worker_exit at 0x7f56534191e0>
  nworkers_changed: <function NumWorkersChanged.nworkers_changed at 0x7f56534192f0>
  on_exit: <function OnExit.on_exit at 0x7f5653419400>
  proxy_protocol: False
  proxy_allow_ips: ['127.0.0.1']
  keyfile: None
  certfile: None
  ssl_version: 2
  cert_reqs: 0
  ca_certs: None
  suppress_ragged_eofs: True
  do_handshake_on_connect: False
  ciphers: None
  raw_paste_global_conf: []
[2019-11-28 10:41:59 +0000] [23666] [INFO] Starting gunicorn 20.0.0
[2019-11-28 10:41:59 +0000] [23666] [DEBUG] Arbiter booted
[2019-11-28 10:41:59 +0000] [23666] [INFO] Listening at: http://127.0.0.1:5000 (23666)
[2019-11-28 10:41:59 +0000] [23666] [INFO] Using worker: threads
[2019-11-28 10:41:59 +0000] [23670] [INFO] Booting worker with pid: 23670
[2019-11-28 10:41:59 +0000] [23670] [ERROR] Exception in worker process
Traceback (most recent call last):
  File "/home/ubuntu/.local/lib/python3.6/site-packages/gunicorn/arbiter.py", line 583, in spawn_worker
    worker.init_process()
  File "/home/ubuntu/.local/lib/python3.6/site-packages/gunicorn/workers/gthread.py", line 92, in init_process
    super().init_process()
  File "/home/ubuntu/.local/lib/python3.6/site-packages/gunicorn/workers/base.py", line 133, in init_process
    self.load_wsgi()
  File "/home/ubuntu/.local/lib/python3.6/site-packages/gunicorn/workers/base.py", line 142, in load_wsgi
    self.wsgi = self.app.wsgi()
  File "/home/ubuntu/.local/lib/python3.6/site-packages/gunicorn/app/base.py", line 67, in wsgi
    self.callable = self.load()
  File "/home/ubuntu/.local/lib/python3.6/site-packages/gunicorn/app/wsgiapp.py", line 49, in load
    return self.load_wsgiapp()
  File "/home/ubuntu/.local/lib/python3.6/site-packages/gunicorn/app/wsgiapp.py", line 39, in load_wsgiapp
    return util.import_app(self.app_uri)
  File "/home/ubuntu/.local/lib/python3.6/site-packages/gunicorn/util.py", line 331, in import_app
    mod = importlib.import_module(module)
  File "/usr/lib/python3.6/importlib/__init__.py", line 126, in import_module
    return _bootstrap._gcd_import(name[level:], package, level)
  File "<frozen importlib._bootstrap>", line 994, in _gcd_import
  File "<frozen importlib._bootstrap>", line 971, in _find_and_load
  File "<frozen importlib._bootstrap>", line 953, in _find_and_load_unlocked
ModuleNotFoundError: No module named 'QnAApi'
[2019-11-28 10:41:59 +0000] [23670] [INFO] Worker exiting (pid: 23670)
[2019-11-28 10:41:59 +0000] [23666] [INFO] Shutting down: Master
[2019-11-28 10:41:59 +0000] [23666] [INFO] Reason: Worker failed to boot.
